Workbook

Sheet PETUNJUK
B2: KALKULATOR COST & HARGA JUAL
B3: Divisi Handling - Lancar Jaya (LA & Handling Services)
B4: Versi 1.0 - Agustus 2026 | Khusus Divisi Handling (LA menyusul terpisah)
B6: CARA PAKAI
B7: Langkah 1 | C7: Buka sheet KALKULATOR. Isi Bagian A (Parameter Paket): jumlah pax, durasi, jumlah hotel, dll.
B8: Langkah 2 | C8: Di Bagian B, pilih YA/TIDAK untuk tiap layanan, dan isi kolom Qty (jumlah unit).
B9: Langkah 3 | C9: Lihat Bagian C (Rekap) - cost dan harga jual keluar otomatis.
B10: Langkah 4 | C10: Buka sheet PROFIT untuk melihat distribusi bagi hasil.
B11: Ubah tarif? | C11: Buka sheet KATALOG. Semua tarif ada di sana dan bisa diedit langsung.
B12: Tambah item? | C12: Isi baris kosong di bagian TAMBAHAN pada sheet KATALOG dan KALKULATOR.
B14: LEGENDA WARNA
B15: Kuning + teks biru | C15: SEL YANG ANDA ISI. Ini input utama - ubah sesuai kebutuhan.
B16: Teks biru | C16: Angka tarif yang bisa diedit (di sheet KATALOG).
B17: Teks hitam | C17: Hasil rumus otomatis. JANGAN DIUBAH.
B18: Teks hijau | C18: Rumus yang mengambil data dari sheet lain. JANGAN DIUBAH.
B19: Abu-abu tebal | C19: Baris total / subtotal.
B21: ISTILAH BASIS BIAYA
B22: PAX | C22: Biaya dikalikan jumlah jama'ah. Contoh: tips porter 20 SAR/pax x 40 pax = 800 SAR.
B23: FLAT | C23: Biaya tetap, tidak terpengaruh jumlah jama'ah. Contoh: fee freelancer 200 SAR.
B24: Qty | C24: Jumlah unit. Contoh: Snack City Tour Qty 2 = dua kali sesi city tour.
B26: CATATAN PENTING
B27: - | C27: Seluruh angka dalam SAR. Kurs SAR-IDR diisi di sheet KALKULATOR dan wajib dicek ulang saat transaksi.
B28: - | C28: Divisi Layanan Khusus & Insidental (jama'ah sakit, wafat, job insidental) TIDAK masuk kalkulator ini karena sifatnya pass-through - ditagihkan terpisah ke client.
B29: - | C29: Biaya legalitas, administrasi PT, konsultan pajak, dan marketing TIDAK masuk overhead - dibebankan ke profit (lihat sheet PROFIT).
B30: - | C30: Sifat biaya layanan Kursi Roda: Proses Umroh = per sesi per jama'ah; Harian = per hari per jama'ah. Isi Qty = jumlah sesi/hari x jumlah jama'ah pengguna.
B31: - | C31: Angka default yang terisi adalah paket standar 40 pax, 9 hari, 2 hotel, katering reguler.

Sheet KATALOG
B2: KATALOG TARIF - DIVISI HANDLING
B3: Semua tarif di bawah bisa diedit. Ubah angka biru, seluruh kalkulator ikut menyesuaikan.
B5: Kode | C5: Komponen | D5: Basis | E5: Rate Standar | F5: Rate Maksimal | G5: Rate Aktif | H5: Catatan
B6: A. HANDLING BANDARA & HOTEL
B7: H01 | C7: Fee Freelancer - Bandara Kedatangan | D7: FLAT | E7: 200 | F7: 200 | G7: =IF(KALKULATOR!$C$12="Maksimal",F7,E7) -> 200 | H7: Per job
B8: H02 | C8: Ongkos Transport PP - Kedatangan | D8: FLAT | E8: 260 | F8: 260 | G8: =IF(KALKULATOR!$C$12="Maksimal",F8,E8) -> 260 | H8: Per job
B9: H03 | C9: Tips Porter - Kedatangan | D9: PAX | E9: 20 | F9: 20 | G9: =IF(KALKULATOR!$C$12="Maksimal",F9,E9) -> 20 | H9: Jeddah T1 bisa 10 SAR/pax
B10: H04 | C10: Tips Muasasah - Kedatangan | D10: FLAT | E10: 20 | F10: 50 | G10: =IF(KALKULATOR!$C$12="Maksimal",F10,E10) -> 20 | H10: Nego
B11: H05 | C11: Fee Freelancer - Check-in Hotel | D11: FLAT | E11: 250 | F11: 250 | G11: =IF(KALKULATOR!$C$12="Maksimal",F11,E11) -> 250 | H11: Per hotel
B12: H06 | C12: Tips Bellboy - Check-in | D12: FLAT | E12: 70 | F12: 100 | G12: =IF(KALKULATOR!$C$12="Maksimal",F12,E12) -> 70 | H12: Per hotel, nego
B13: H07 | C13: Fee Freelancer - Check-out Hotel | D13: FLAT | E13: 200 | F13: 200 | G13: =IF(KALKULATOR!$C$12="Maksimal",F13,E13) -> 200 | H13: Per hotel
B14: H08 | C14: Tips Bellboy - Check-out | D14: FLAT | E14: 80 | F14: 150 | G14: =IF(KALKULATOR!$C$12="Maksimal",F14,E14) -> 80 | H14: Per hotel, nego
B15: H09 | C15: Tips Muasasah - Check-out | D15: FLAT | E15: 20 | F15: 50 | G15: =IF(KALKULATOR!$C$12="Maksimal",F15,E15) -> 20 | H15: 1x per trip, nego
B16: H10 | C16: Fee Freelancer - Bandara Kepulangan | D16: FLAT | E16: 250 | F16: 250 | G16: =IF(KALKULATOR!$C$12="Maksimal",F16,E16) -> 250 | H16: Per job
B17: H11 | C17: Ongkos Transport PP - Kepulangan | D17: FLAT | E17: 260 | F17: 260 | G17: =IF(KALKULATOR!$C$12="Maksimal",F17,E17) -> 260 | H17: Per job
B18: H12 | C18: Tips Porter - Kepulangan | D18: PAX | E18: 20 | F18: 20 | G18: =IF(KALKULATOR!$C$12="Maksimal",F18,E18) -> 20 | H18: Jeddah T1 bisa 10 SAR/pax
B19: H13 | C19: Tips Petugas Zamzam | D19: FLAT | E19: 20 | F19: 20 | G19: =IF(KALKULATOR!$C$12="Maksimal",F19,E19) -> 20 | H19: Penataan galon di troli
B20: B. MUTHOWIF
B21: M01 | C21: Fee Muthowif (per hari) | D21: FLAT | E21: 250 | F21: 250 | G21: =IF(KALKULATOR!$C$12="Maksimal",F21,E21) -> 250 | H21: 1 orang per grup/bus
B22: M02 | C22: Ongkos Muthowif PP | D22: FLAT | E22: 300 | F22: 300 | G22: =IF(KALKULATOR!$C$12="Maksimal",F22,E22) -> 300 | H22: 150 x 2
B23: M03 | C23: Fee Muthowifah - Bimbingan Raudhoh | D23: FLAT | E23: 200 | F23: 200 | G23: =IF(KALKULATOR!$C$12="Maksimal",F23,E23) -> 200 | H23: 1x per trip
B24: M04 | C24: Kursi Roda - Proses Umroh (per sesi/jama'ah) | D24: FLAT | E24: 250 | F24: 250 | G24: =IF(KALKULATOR!$C$12="Maksimal",F24,E24) -> 250 | H24: Thawaf & Sa'i
B25: M05 | C25: Kursi Roda - Harian (per hari/jama'ah) | D25: FLAT | E25: 250 | F25: 250 | G25: =IF(KALKULATOR!$C$12="Maksimal",F25,E25) -> 250 | H25: Termasuk thawaf & sa'i
B26: C. KATERING & SNACK
B27: K01 | C27: Nasi Box - REGULER | D27: PAX | E27: 15 | F27: 15 | G27: =IF(KALKULATOR!$C$12="Maksimal",F27,E27) -> 15 | H27: Bandara-Kota
B28: K02 | C28: Nasi Box - PREMIUM | D28: PAX | E28: 20 | F28: 20 | G28: =IF(KALKULATOR!$C$12="Maksimal",F28,E28) -> 20 | H28: Bandara-Kota
B29: K03 | C29: Snack City Tour - REGULER | D29: PAX | E29: 6.5 | F29: 6.5 | G29: =IF(KALKULATOR!$C$12="Maksimal",F29,E29) -> 6.5 | H29: Per sesi
B30: K04 | C30: Snack City Tour - PREMIUM | D30: PAX | E30: 10 | F30: 10 | G30: =IF(KALKULATOR!$C$12="Maksimal",F30,E30) -> 10 | H30: Per sesi
B31: K05 | C31: Snack Madinah-Makkah - REGULER | D31: PAX | E31: 8 | F31: 8 | G31: =IF(KALKULATOR!$C$12="Maksimal",F31,E31) -> 8 | H31: Atau sebaliknya
B32: K06 | C32: Snack Madinah-Makkah - PREMIUM | D32: PAX | E32: 12 | F32: 12 | G32: =IF(KALKULATOR!$C$12="Maksimal",F32,E32) -> 12 | H32: Atau sebaliknya
B33: K07 | C33: Air Zamzam Galon 5L (bawa pulang) | D33: PAX | E33: 12.5 | F33: 12.5 | G33: =IF(KALKULATOR!$C$12="Maksimal",F33,E33) -> 12.5 | H33: Per jama'ah
B34: K08 | C34: Albaik Kepulangan | D34: PAX | E34: 25 | F34: 25 | G34: =IF(KALKULATOR!$C$12="Maksimal",F34,E34) -> 25 | H34: Add-on / paket premium
B35: K09 | C35: Welcoming Drink (zamzam + cup 50pcs) | D35: FLAT | E35: 22.5 | F35: 22.5 | G35: =IF(KALKULATOR!$C$12="Maksimal",F35,E35) -> 22.5 | H35: 1 galon cukup s/d 50 pax
B36: D. TIP DRIVER BUS
B37: D01 | C37: Tip Driver - Bandara ke Hotel | D37: FLAT | E37: 100 | F37: 100 | G37: =IF(KALKULATOR!$C$12="Maksimal",F37,E37) -> 100 | H37: Per trip
B38: D02 | C38: Tip Driver - City Tour (per sesi) | D38: FLAT | E38: 50 | F38: 50 | G38: =IF(KALKULATOR!$C$12="Maksimal",F38,E38) -> 50 | H38: Per sesi
B39: D03 | C39: Tip Driver - Madinah ke Makkah | D39: FLAT | E39: 100 | F39: 100 | G39: =IF(KALKULATOR!$C$12="Maksimal",F39,E39) -> 100 | H39: Atau sebaliknya
B40: D04 | C40: Tip Driver - Hotel ke Bandara | D40: FLAT | E40: 100 | F40: 100 | G40: =IF(KALKULATOR!$C$12="Maksimal",F40,E40) -> 100 | H40: Per trip
B41: E. PHOTOGRAPHY
B42: P01 | C42: Sesi Standar (CT/Nabawi/Umroh Wajib) | D42: FLAT | E42: 230 | F42: 230 | G42: =IF(KALKULATOR!$C$12="Maksimal",F42,E42) -> 230 | H42: Per sesi
...

Sheet KALKULATOR
B2: KALKULATOR COST & HARGA JUAL - DIVISI HANDLING
B3: Isi sel kuning. Sisanya otomatis.
B5: A. PARAMETER PAKET
B6: Jumlah Jama'ah (Pax) | C6: 40 | D6: Total jama'ah dalam grup
B7: Durasi Paket (hari) | C7: 9 | D7: Termasuk hari perjalanan
B8: Hari Muthowif Bertugas | C8: 7 | D8: Biasanya durasi paket dikurangi 2
B9: Jumlah Hotel - Check-in | C9: 2 | D9: Madinah & Makkah = 2
B10: Jumlah Hotel - Check-out | C10: 2 | D10: Madinah & Makkah = 2
B11: Kelas Katering | C11: Reguler | D11: Pilih: Reguler atau Premium
B12: Skenario Tips | C12: Standar | D12: Pilih: Standar atau Maksimal
B13: Overhead (%) | C13: 0.05 | D13: Atribut, laundry, komunikasi, transport koordinasi
B14: Buffer Risiko (%) | C14: 0.05 | D14: Delay, freelancer batal, nego tips gagal
B15: Target Margin (%) | C15: 0.2 | D15: Margin yang diinginkan atas harga jual
B16: Kurs SAR ke IDR | C16: 4800 | D16: Cek ulang saat transaksi
B18: B. PILIHAN LAYANAN - pilih YA/TIDAK dan isi Qty
B19: Komponen | C19: Aktif | D19: Qty | E19: Basis | F19: Rate (SAR) | G19: Subtotal (SAR) | H19: Per Pax
B20: HANDLING
B21: Fee Freelancer - Bandara Kedatangan | C21: YA | D21: 1 | E21: =KATALOG!D7 -> FLAT | F21: =KATALOG!G7 -> 200 | G21: =IF($C21="YA",$D21*$F21*IF($E21="PAX",$C$6,1),0) -> 200 | H21: =IF($C$6=0,0,G21/$C$6) -> 5
B22: Ongkos Transport PP - Kedatangan | C22: YA | D22: 1 | E22: =KATALOG!D8 -> FLAT | F22: =KATALOG!G8 -> 260 | G22: =IF($C22="YA",$D22*$F22*IF($E22="PAX",$C$6,1),0) -> 260 | H22: =IF($C$6=0,0,G22/$C$6) -> 6.5
B23: Tips Porter - Kedatangan | C23: YA | D23: 1 | E23: =KATALOG!D9 -> PAX | F23: =KATALOG!G9 -> 20 | G23: =IF($C23="YA",$D23*$F23*IF($E23="PAX",$C$6,1),0) -> 800 | H23: =IF($C$6=0,0,G23/$C$6) -> 20
B24: Tips Muasasah - Kedatangan | C24: YA | D24: 1 | E24: =KATALOG!D10 -> FLAT | F24: =KATALOG!G10 -> 20 | G24: =IF($C24="YA",$D24*$F24*IF($E24="PAX",$C$6,1),0) -> 20 | H24: =IF($C$6=0,0,G24/$C$6) -> 0.5
B25: Fee Freelancer - Check-in Hotel | C25: YA | D25: =$C$9 -> 2 | E25: =KATALOG!D11 -> FLAT | F25: =KATALOG!G11 -> 250 | G25: =IF($C25="YA",$D25*$F25*IF($E25="PAX",$C$6,1),0) -> 500 | H25: =IF($C$6=0,0,G25/$C$6) -> 12.5
B26: Tips Bellboy - Check-in | C26: YA | D26: =$C$9 -> 2 | E26: =KATALOG!D12 -> FLAT | F26: =KATALOG!G12 -> 70 | G26: =IF($C26="YA",$D26*$F26*IF($E26="PAX",$C$6,1),0) -> 140 | H26: =IF($C$6=0,0,G26/$C$6) -> 3.5
B27: Fee Freelancer - Check-out Hotel | C27: YA | D27: =$C$10 -> 2 | E27: =KATALOG!D13 -> FLAT | F27: =KATALOG!G13 -> 200 | G27: =IF($C27="YA",$D27*$F27*IF($E27="PAX",$C$6,1),0) -> 400 | H27: =IF($C$6=0,0,G27/$C$6) -> 10
B28: Tips Bellboy - Check-out | C28: YA | D28: =$C$10 -> 2 | E28: =KATALOG!D14 -> FLAT | F28: =KATALOG!G14 -> 80 | G28: =IF($C28="YA",$D28*$F28*IF($E28="PAX",$C$6,1),0) -> 160 | H28: =IF($C$6=0,0,G28/$C$6) -> 4
B29: Tips Muasasah - Check-out | C29: YA | D29: 1 | E29: =KATALOG!D15 -> FLAT | F29: =KATALOG!G15 -> 20 | G29: =IF($C29="YA",$D29*$F29*IF($E29="PAX",$C$6,1),0) -> 20 | H29: =IF($C$6=0,0,G29/$C$6) -> 0.5
B30: Fee Freelancer - Bandara Kepulangan | C30: YA | D30: 1 | E30: =KATALOG!D16 -> FLAT | F30: =KATALOG!G16 -> 250 | G30: =IF($C30="YA",$D30*$F30*IF($E30="PAX",$C$6,1),0) -> 250 | H30: =IF($C$6=0,0,G30/$C$6) -> 6.25
B31: Ongkos Transport PP - Kepulangan | C31: YA | D31: 1 | E31: =KATALOG!D17 -> FLAT | F31: =KATALOG!G17 -> 260 | G31: =IF($C31="YA",$D31*$F31*IF($E31="PAX",$C$6,1),0) -> 260 | H31: =IF($C$6=0,0,G31/$C$6) -> 6.5
B32: Tips Porter - Kepulangan | C32: YA | D32: 1 | E32: =KATALOG!D18 -> PAX | F32: =KATALOG!G18 -> 20 | G32: =IF($C32="YA",$D32*$F32*IF($E32="PAX",$C$6,1),0) -> 800 | H32: =IF($C$6=0,0,G32/$C$6) -> 20
B33: Tips Petugas Zamzam | C33: YA | D33: 1 | E33: =KATALOG!D19 -> FLAT | F33: =KATALOG!G19 -> 20 | G33: =IF($C33="YA",$D33*$F33*IF($E33="PAX",$C$6,1),0) -> 20 | H33: =IF($C$6=0,0,G33/$C$6) -> 0.5
B34: SUBTOTAL HANDLING | G34: =SUM(G21:G33) -> 3830 | H34: =IF($C$6=0,0,G34/$C$6) -> 95.75
B36: MUTHOWIF
B37: Fee Muthowif (per hari) | C37: YA | D37: =$C$8 -> 7 | E37: =KATALOG!D21 -> FLAT | F37: =KATALOG!G21 -> 250 | G37: =IF($C37="YA",$D37*$F37*IF($E37="PAX",$C$6,1),0) -> 1750 | H37: =IF($C$6=0,0,G37/$C$6) -> 43.75
B38: Ongkos Muthowif PP | C38: YA | D38: 1 | E38: =KATALOG!D22 -> FLAT | F38: =KATALOG!G22 -> 300 | G38: =IF($C38="YA",$D38*$F38*IF($E38="PAX",$C$6,1),0) -> 300 | H38: =IF($C$6=0,0,G38/$C$6) -> 7.5
B39: Fee Muthowifah - Bimbingan Raudhoh | C39: YA | D39: 1 | E39: =KATALOG!D23 -> FLAT | F39: =KATALOG!G23 -> 200 | G39: =IF($C39="YA",$D39*$F39*IF($E39="PAX",$C$6,1),0) -> 200 | H39: =IF($C$6=0,0,G39/$C$6) -> 5
B40: Kursi Roda - Proses Umroh (sesi x jama'ah) | C40: TIDAK | D40: 0 | E40: =KATALOG!D24 -> FLAT | F40: =KATALOG!G24 -> 250 | G40: =IF($C40="YA",$D40*$F40*IF($E40="PAX",$C$6,1),0) -> 0 | H40: =IF($C$6=0,0,G40/$C$6) -> 0
B41: Kursi Roda - Harian (hari x jama'ah) | C41: TIDAK | D41: 0 | E41: =KATALOG!D25 -> FLAT | F41: =KATALOG!G25 -> 250 | G41: =IF($C41="YA",$D41*$F41*IF($E41="PAX",$C$6,1),0) -> 0 | H41: =IF($C$6=0,0,G41/$C$6) -> 0
B42: SUBTOTAL MUTHOWIF | G42: =SUM(G37:G41) -> 2250 | H42: =IF($C$6=0,0,G42/$C$6) -> 56.25
B44: KATERING & SNACK
B45: Nasi Box (Bandara-Kota) | C45: YA | D45: 1 | E45: =IF($C$11="Premium",KATALOG!D28,KATALOG!D27) -> PAX | F45: =IF($C$11="Premium",KATALOG!G28,KATALOG!G27) -> 15 | G45: =IF($C45="YA",$D45*$F45*IF($E45="PAX",$C$6,1),0) -> 600 | H45: =IF($C$6=0,0,G45/$C$6) -> 15
...

Sheet PROFIT
B2: DISTRIBUSI PROFIT
B3: Mengambil angka Profit dari sheet KALKULATOR (per 1 grup)
B5: A. URUTAN PEMBAGIAN (per 1 grup)
B6: Keterangan | C6: SAR | D6: IDR
B7: Profit Kotor (dari KALKULATOR) | C7: =KALKULATOR!G91 -> 2321.6875 | D7: =C7*KALKULATOR!$C$16 -> 11144100
B8: (-) Biaya di luar anggaran (legalitas, konsultan, marketing) | C8: 0 | D8: =C8*KALKULATOR!$C$16 -> 0
B9: PROFIT BERSIH OPERASIONAL | C9: =C7-C8 -> 2321.6875 | D9: =C9*KALKULATOR!$C$16 -> 11144100
B10: (-) Gaji Direktur (35%) | C10: =C9*0.35 -> 812.59063 | D10: =C10*KALKULATOR!$C$16 -> 3900435
B11: Laba Kena Pajak | C11: =C9-C10 -> 1509.0969 | D11: =C11*KALKULATOR!$C$16 -> 7243665
B12: Tarif PPh Badan (%) | C12: 0.11 | D12: Pasal 31E: 11% untuk omzet s/d Rp 4,8 M
B13: (-) PPh Badan | C13: =C11*C12 -> 166.00066 | D13: =C13*KALKULATOR!$C$16 -> 796803.15
B14: LABA BERSIH | C14: =C11-C13 -> 1343.0962 | D14: =C14*KALKULATOR!$C$16 -> 6446861.8
B16: B. GAJI DIREKTUR (35% dari Profit Bersih Operasional)
B17: Personel / Jabatan | C17: SAR | D17: IDR
B18: Ocid - Dirut + Direktur LA | C18: =C9*0.14 -> 325.03625 | D18: =C18*KALKULATOR!$C$16 -> 1560174
B19: Azzam - Dir. Handling + Dir. Marketing | C19: =C9*0.14 -> 325.03625 | D19: =C19*KALKULATOR!$C$16 -> 1560174
B20: Andika - Direktur Keuangan | C20: =C9*0.07 -> 162.51812 | D20: =C20*KALKULATOR!$C$16 -> 780087
B21: TOTAL GAJI DIREKTUR | C21: =SUM(C18:C20) -> 812.59063 | D21: =C21*KALKULATOR!$C$16 -> 3900435
B23: C. PEMBAGIAN LABA BERSIH
B24: Pos | C24: SAR | D24: IDR
B25: Tabungan / Dana Darurat (23%) | C25: =C14*0.23 -> 308.91213 | D25: =C25*KALKULATOR!$C$16 -> 1482778.2
B26: Dividen Owner (77%) - dibagi tiap 6 bulan | C26: =C14*0.77 -> 1034.1841 | D26: =C26*KALKULATOR!$C$16 -> 4964083.6
B28: D. PROYEKSI TAHUNAN
B29: Jumlah Grup per Bulan | C29: 4
B30: Jumlah Grup per Tahun | C30: =C29*12 -> 48
B31: Pos | C31: Per Tahun (SAR) | D31: Per Tahun (IDR)
B32: Profit Bersih Operasional | C32: =C9*C30 -> 111441 | D32: =C32*KALKULATOR!$C$16 -> 534916800
B33: Gaji Ocid | C33: =C18*C30 -> 15601.74 | D33: =C33*KALKULATOR!$C$16 -> 74888352
B34: Gaji Azzam | C34: =C19*C30 -> 15601.74 | D34: =C34*KALKULATOR!$C$16 -> 74888352
B35: Gaji Andika | C35: =C20*C30 -> 7800.87 | D35: =C35*KALKULATOR!$C$16 -> 37444176
B36: PPh Badan | C36: =C13*C30 -> 7968.0315 | D36: =C36*KALKULATOR!$C$16 -> 38246551
B37: Laba Bersih | C37: =C14*C30 -> 64468.618 | D37: =C37*KALKULATOR!$C$16 -> 3.0944937e+08
B38: Tabungan | C38: =C25*C30 -> 14827.782 | D38: =C38*KALKULATOR!$C$16 -> 71173355
B39: Dividen Owner | C39: =C26*C30 -> 49640.836 | D39: =C39*KALKULATOR!$C$16 -> 2.3827601e+08
B41: CATATAN: 1. Gaji Direktur diperlakukan sebagai BIAYA perusahaan, sehingga mengurangi laba kena pajak. 2. PPh Badan dihitung SEBELUM pembagian Tabungan & Dividen. Ini mencegah kekurangan dana saat pembagian. 3. Proporsi Tabungan : Dividen = 23% : 77% (setara 15% : 50% dari profit sebelum pajak). 4. Biaya legalitas, administrasi PT, konsultan pajak, dan marketing diisi di baris 'Biaya di luar anggaran'. 5. Angka pajak di sini hanya estimasi kasar - wajib dikonfirmasi ke konsultan pajak.
